<?xml version="1.0" ?>
<!-- =================================================================================== -->
<!-- |    This document was autogenerated by xacro from sia_7f_arm.urdf.xacro          | -->
<!-- |    EDITING THIS FILE BY HAND IS NOT RECOMMENDED                                 | -->
<!-- =================================================================================== -->
<!-- sia 7f  Manipulator -->
<robot name="sia_7f_arm" xmlns:xacro="http://www.ros.org/wiki/xacro">
  <!-- arbitrary value for mass -->
  <!-- ros_control plugin -->
  <gazebo>
    <plugin filename="libgazebo_ros_control.so" name="gazebo_ros_control">
      <robotNamespace>/sia_7f_arm</robotNamespace>
      <robotSimType>gazebo_ros_control/DefaultRobotHWSim</robotSimType>
      <legacyModeNS>true</legacyModeNS>
    </plugin>
  </gazebo>
  <!-- Gazebo-Specific Link Properties -->
  <!-- Base Link -->
  <gazebo reference="sia_7f_base_link">
    <material>Gazebo/Orange</material>
  </gazebo>
  <!-- Link1 -->
  <gazebo reference="sia_7f_link1">
    <material>Gazebo/Orange</material>
  </gazebo>
  <!-- Link2 -->
  <gazebo reference="sia_7f_link2">
    <mu1>0.2</mu1>
    <mu2>0.2</mu2>
    <material>Gazebo/Black</material>
  </gazebo>
  <!-- Link3 -->
  <gazebo reference="sia_7f_link3">
    <mu1>0.2</mu1>
    <mu2>0.2</mu2>
    <material>Gazebo/Orange</material>
  </gazebo>
  <!-- Link4 -->
  <gazebo reference="sia_7f_link4">
    <mu1>0.2</mu1>
    <mu2>0.2</mu2>
    <material>Gazebo/Black</material>
  </gazebo>
  <!-- Link5 -->
  <gazebo reference="sia_7f_link5">
    <mu1>0.2</mu1>
    <mu2>0.2</mu2>
    <material>Gazebo/Black</material>
  </gazebo>
  <!-- Gripper -->
  <gazebo reference="sia_7f_gripper">
    <mu1>0.2</mu1>
    <mu2>0.2</mu2>
    <material>Gazebo/Black</material>
  </gazebo>
  <!-- 7f_gripper_left_inner_knuckle -->
  <gazebo reference="7f_gripper_left_inner_knuckle">
    <mu1>0.2</mu1>
    <mu2>0.2</mu2>
    <material>Gazebo/Red</material>
  </gazebo>
  <!-- 7f_gripper_left_outer_finger -->
  <gazebo reference="7f_gripper_left_outer_finger">
    <mu1>0.2</mu1>
    <mu2>0.2</mu2>
    <material>Gazebo/Red</material>
  </gazebo>
  <!-- 7f_gripper_left_inner_finger -->
  <gazebo reference="7f_gripper_left_inner_finger">
    <mu1>0.2</mu1>
    <mu2>0.2</mu2>
    <material>Gazebo/Red</material>
  </gazebo>
  <!-- 7f_gripper_right_inner_knuckle -->
  <gazebo reference="7f_gripper_right_inner_knuckle">
    <mu1>0.2</mu1>
    <mu2>0.2</mu2>
    <material>Gazebo/Red</material>
  </gazebo>
  <!-- 7f_gripper_right_outer_finger -->
  <gazebo reference="7f_gripper_right_outer_finger">
    <mu1>0.2</mu1>
    <mu2>0.2</mu2>
    <material>Gazebo/Red</material>
  </gazebo>
  <!-- 7f_gripper_right_inner_finger -->
  <gazebo reference="7f_gripper_right_inner_finger">
    <mu1>0.2</mu1>
    <mu2>0.2</mu2>
    <material>Gazebo/Red</material>
  </gazebo>
  <!-- camera_link -->
  <gazebo reference="camera_link">
    <mu1>0.2</mu1>
    <mu2>0.2</mu2>
    <material>Gazebo/Red</material>
  </gazebo>
  <!-- camera -->
  <gazebo reference="camera_link">
    <sensor name="camera1" type="camera">
      <update_rate>30.0</update_rate>
      <camera name="head">
        <horizontal_fov>1.3962634</horizontal_fov>
        <image>
          <width>800</width>
          <height>800</height>
          <format>R8G8B8</format>
        </image>
        <clip>
          <near>0.02</near>
          <far>300</far>
        </clip>
        <noise>
          <type>gaussian</type>
          <!-- Noise is sampled independently per pixel on each frame.  
               That pixel's noise value is added to each of its color
               channels, which at that point lie in the range [0,1]. -->
          <mean>0.0</mean>
          <stddev>0.007</stddev>
        </noise>
      </camera>
      <plugin filename="libgazebo_ros_camera.so" name="camera_controller">
        <alwaysOn>true</alwaysOn>
        <updateRate>0.0</updateRate>
        <cameraName>rrbot/camera1</cameraName>
        <imageTopicName>image_raw</imageTopicName>
        <cameraInfoTopicName>camera_info</cameraInfoTopicName>
        <frameName>camera_link</frameName>
        <hackBaseline>0.07</hackBaseline>
        <distortionK1>0.0</distortionK1>
        <distortionK2>0.0</distortionK2>
        <distortionK3>0.0</distortionK3>
        <distortionT1>0.0</distortionT1>
        <distortionT2>0.0</distortionT2>
      </plugin>
    </sensor>
  </gazebo>
  <gazebo reference="left_camera_frame">
    <sensor name="stereo_camera" type="multicamera">
      <update_rate>30.0</update_rate>
      <camera name="left">
        <horizontal_fov>1.3962634</horizontal_fov>
        <image>
          <width>800</width>
          <height>800</height>
          <format>R8G8B8</format>
        </image>
        <clip>
          <near>0.02</near>
          <far>300</far>
        </clip>
        <noise>
          <type>gaussian</type>
          <mean>0.0</mean>
          <stddev>0.007</stddev>
        </noise>
      </camera>
      <camera name="right">
        <pose>0 -0.07 0 0 0 0</pose>
        <horizontal_fov>1.3962634</horizontal_fov>
        <image>
          <width>800</width>
          <height>800</height>
          <format>R8G8B8</format>
        </image>
        <clip>
          <near>0.02</near>
          <far>300</far>
        </clip>
        <noise>
          <type>gaussian</type>
          <mean>0.0</mean>
          <stddev>0.007</stddev>
        </noise>
      </camera>
      <plugin filename="libgazebo_ros_multicamera.so" name="stereo_camera_controller">
        <alwaysOn>true</alwaysOn>
        <updateRate>0.0</updateRate>
        <cameraName>multisense_sl/camera</cameraName>
        <imageTopicName>image_raw</imageTopicName>
        <cameraInfoTopicName>camera_info</cameraInfoTopicName>
        <frameName>left_camera_optical_frame</frameName>
        <!--<rightFrameName>right_camera_optical_frame</rightFrameName>-->
        <hackBaseline>0.07</hackBaseline>
        <distortionK1>0.0</distortionK1>
        <distortionK2>0.0</distortionK2>
        <distortionK3>0.0</distortionK3>
        <distortionT1>0.0</distortionT1>
        <distortionT2>0.0</distortionT2>
      </plugin>
    </sensor>
  </gazebo>
  <!-- zed camera -->
  <!--xacro:unless value="$(optenv DISABLE_GAZEBO_CAMERA false)"-->
  <gazebo reference="camera_link">
    <sensor name="zed_camera_left_sensor" type="camera">
      <update_rate>30.0</update_rate>
      <!-- math.atan(320 / 687.8065795898438) * 2 -->
      <camera name="zed_camera_left_camera">
        <horizontal_fov>0.8709216071359963</horizontal_fov>
        <image>
          <width>640</width>
          <height>480</height>
          <format>B8G8R8</format>
        </image>
        <clip>
          <near>0.02</near>
          <far>300</far>
        </clip>
        <noise>
          <type>gaussian</type>
          <mean>0.0</mean>
          <stddev>0.007</stddev>
        </noise>
      </camera>
      <plugin filename="libgazebo_ros_camera.so" name="camera_controller">
        <alwaysOn>true</alwaysOn>
        <updateRate>30.0</updateRate>
        <cameraName>/camera/zed</cameraName>
        <imageTopicName>rgb/image_rect_color</imageTopicName>
        <cameraInfoTopicName>rgb/camera_info</cameraInfoTopicName>
        <frameName>camera_link</frameName>
        <hackBaseline>0</hackBaseline>
        <!-- set this to 0.12 for the second camera -->
        <distortionK1>0.0</distortionK1>
        <distortionK2>0.0</distortionK2>
        <distortionK3>0.0</distortionK3>
        <distortionT1>0.0</distortionT1>
        <distortionT2>0.0</distortionT2>
      </plugin>
    </sensor>
  </gazebo>
  <!--/xacro:unless-->
  <material name="black">
    <color rgba="0.0 0.0 0.0 1.0"/>
  </material>
  <material name="blue">
    <color rgba="0.0 0.0 0.8 1.0"/>
  </material>
  <material name="green">
    <color rgba="0.0 0.8 0.0 1.0"/>
  </material>
  <material name="grey">
    <color rgba="0.2 0.2 0.2 1.0"/>
  </material>
  <material name="orange">
    <color rgba="1.0 0.423529411765 0.0392156862745 1.0"/>
  </material>
  <material name="brown">
    <color rgba="0.870588235294 0.811764705882 0.764705882353 1.0"/>
  </material>
  <material name="red">
    <color rgba="0.8 0.0 0.0 1.0"/>
  </material>
  <material name="white">
    <color rgba="1.0 1.0 1.0 1.0"/>
  </material>
  <!-- Used for fixing robot to Gazebo 'base_link' -->
  <!--link name="world"/>
  <joint name="fixed" type="fixed">
    <parent link="world"/>
    <child link="sia_7f_base_link"/>
  </joint-->
  <!-- Link -->
  <link name="world" />

  <link name="sia_7f_base_link">
    <inertial>
      <origin rpy="0 0 0" xyz="0.000552121264427677 -0.00865338938246674 0.0629980388602465"/>
      <mass value="8.90916939429998"/>
      <inertia ixx="0.0798846804394286" ixy="0.00101896497997934" ixz="1.79149005312292E-08" iyy="0.0398392472247972" iyz="-1.92493760430197E-07" izz="0.0861996313421393"/>
    </inertial>
    <visual>
      <origin rpy="0 0 0" xyz="0 0 0"/>
      <geometry>
        <mesh filename="package://sia_7f_arm_description/meshes/sia_7f_base_link.STL"/>
      </geometry>
      <material name="">
        <color rgba="0.658823529411765 0.654901960784314 0.403921568627451 1"/>
      </material>
    </visual>
    <collision>
      <origin rpy="0 0 0" xyz="0 0 0"/>
      <geometry>
        <mesh filename="package://sia_7f_arm_description/meshes/sia_7f_base_link_collision.stl"/>
      </geometry>
    </collision>
  </link>
  <joint name="world_to_base_link=" type="fixed">
    <parent link="world"/>
    <child link="sia_7f_base_link"/>
  </joint>
  <link name="sia_7f_link1">
    <inertial>
      <origin rpy="0 0 0" xyz="-0.00477248755414533 0.054864800395508 0.0175766290434111"/>
      <mass value="2.47722330671474"/>
      <inertia ixx="0.00856904452268372" ixy="-0.000666387544351584" ixz="-0.00020780000270144" iyy="0.00626682533558291" iyz="-0.00191364332827914" izz="0.00774719682029338"/>
    </inertial>
    <visual>
      <origin rpy="0 0 0" xyz="0 0 0"/>
      <geometry>
        <mesh filename="package://sia_7f_arm_description/meshes/sia_7f_link1.STL"/>
      </geometry>
      <material name="">
        <color rgba="0.752941176470588 0.752941176470588 0.752941176470588 1"/>
      </material>
    </visual>
    <collision>
      <origin rpy="0 0 0" xyz="0 0 0"/>
      <geometry>
        <mesh filename="package://sia_7f_arm_description/meshes/sia_7f_link1_collision.stl"/>
      </geometry>
    </collision>
  </link>

  <joint name="sia_7f_joint1" type="revolute">
    <origin rpy="0 0 0" xyz="-0.01372 0.16593 0.063"/>
    <parent link="sia_7f_base_link"/>
    <child link="sia_7f_link1"/>
    <axis xyz="0 0 1"/>
    <limit effort="1" lower="-1" upper="1" velocity="1"/>
  </joint>

  <transmission name="sia_7f_joint1_trans">
    <type>transmission_interface/SimpleTransmission</type>
    <joint name="sia_7f_joint1">
      <hardwareInterface>hardware_interface/PositionJointInterface</hardwareInterface>
    </joint>
    <actuator name="sia_7f_joint1_motor">
      <hardwareInterface>hardware_interface/PositionJointInterface</hardwareInterface>
      <mechanicalReduction>1</mechanicalReduction>
    </actuator>
  </transmission>

  <link name="sia_7f_link2">
    <inertial>
      <origin rpy="0 0 0" xyz="-0.476596737714854 -0.0343271575833397 0.000671430138102419"/>
      <mass value="20.0355772787931"/>
      <inertia ixx="0.102519655384336" ixy="0.00106744013777462" ixz="-1.43845343979595E-06" iyy="1.27050785093863" iyz="0.000101717905515995" izz="1.30077323793537"/>
    </inertial>
    <visual>
      <origin rpy="0 0 0" xyz="0 0 0"/>
      <geometry>
        <mesh filename="package://sia_7f_arm_description/meshes/sia_7f_link2.STL"/>
      </geometry>
      <material name="">
        <color rgba="0.752941176470588 0.752941176470588 0.752941176470588 1"/>
      </material>
    </visual>
    <collision>
      <origin rpy="0 0 0" xyz="0 0 0"/>
      <geometry>
        <mesh filename="package://sia_7f_arm_description/meshes/sia_7f_link2_collision.stl"/>
      </geometry>
    </collision>
  </link>

  <joint name="sia_7f_joint2" type="revolute">
    <origin rpy="0 1.5708 0" xyz="0 0.0925 0.0785"/>
    <parent link="sia_7f_link1"/>
    <child link="sia_7f_link2"/>
    <axis xyz="0 0 1"/>
    <limit effort="1" lower="-1.57" upper="0" velocity="1"/>
  </joint>
 
  <transmission name="sia_7f_joint2_trans">
    <type>transmission_interface/SimpleTransmission</type>
    <joint name="sia_7f_joint2">
      <hardwareInterface>hardware_interface/PositionJointInterface</hardwareInterface>
    </joint>
    <actuator name="sia_7f_joint2_motor">
      <hardwareInterface>hardware_interface/PositionJointInterface</hardwareInterface>
      <mechanicalReduction>1</mechanicalReduction>
    </actuator>
  </transmission>

  <link name="sia_7f_link3">
    <inertial>
      <origin rpy="0 0 0" xyz="0.0439931321108593 -0.114052744355428 -0.000160934180912634"/>
      <mass value="14.7884795223293"/>
      <inertia ixx="0.0621784176312451" ixy="0.00397107315733908" ixz="-0.000104775851529477" iyy="0.0886327350633775" iyz="0.000272407076111288" izz="0.10282964488277"/>
    </inertial>
    <visual>
      <origin rpy="0 0 0" xyz="0 0 0"/>
      <geometry>
        <mesh filename="package://sia_7f_arm_description/meshes/sia_7f_link3.STL"/>
      </geometry>
      <material name="">
        <color rgba="0.752941176470588 0.752941176470588 0.752941176470588 1"/>
      </material>
    </visual>
    <collision>
      <origin rpy="0 0 0" xyz="0 0 0"/>
      <geometry>
        <mesh filename="package://sia_7f_arm_description/meshes/sia_7f_link3_collision.stl"/>
      </geometry>
    </collision>
  </link>

  <joint name="sia_7f_joint3" type="revolute">
    <origin rpy="-3.1416 -2.22E-20 -2.7522E-36" xyz="-0.95 0 0"/>
    <parent link="sia_7f_link2"/>
    <child link="sia_7f_link3"/>
    <axis xyz="0 0 -1"/>
    <limit effort="1" lower="0" upper="1.57" velocity="1"/>
  </joint>

  <transmission name="sia_7f_joint3_trans">
    <type>transmission_interface/SimpleTransmission</type>
    <joint name="sia_7f_joint3">
      <hardwareInterface>hardware_interface/PositionJointInterface</hardwareInterface>
    </joint>
    <actuator name="sia_7f_joint3_motor">
      <hardwareInterface>hardware_interface/PositionJointInterface</hardwareInterface>
      <mechanicalReduction>1</mechanicalReduction>
    </actuator>
  </transmission>

  <link name="sia_7f_link4">
    <inertial>
      <origin rpy="0 0 0" xyz="-5.33238969312733E-05 0.00165079495812348 -0.194398123860009"/>
      <mass value="4.55297800469122"/>
      <inertia ixx="0.0741947142976996" ixy="-4.27258703415459E-07" ixz="-4.89922226415979E-05" iyy="0.0754938009612946" iyz="-0.00130361184563876" izz="0.0141512466354037"/>
    </inertial>
    <visual>
      <origin rpy="0 0 0" xyz="0 0 0"/>
      <geometry>
        <mesh filename="package://sia_7f_arm_description/meshes/sia_7f_link4.STL"/>
      </geometry>
      <material name="">
        <color rgba="0.752941176470588 0.752941176470588 0.752941176470588 1"/>
      </material>
    </visual>
    <collision>
      <origin rpy="0 0 0" xyz="0 0 0"/>
      <geometry>
        <mesh filename="package://sia_7f_arm_description/meshes/sia_7f_link4_collision.stl"/>
      </geometry>
    </collision>
  </link>

  <joint name="sia_7f_joint4" type="revolute">
    <origin rpy="3.1416 1.5708 0" xyz="0.139 -0.127 0"/>
    <parent link="sia_7f_link3"/>
    <child link="sia_7f_link4"/>
    <axis xyz="0 0 1"/>
    <limit effort="1" lower="-0.7" upper="0.7" velocity="1"/>
  </joint>

  <transmission name="sia_7f_joint4_trans">
    <type>transmission_interface/SimpleTransmission</type>
    <joint name="sia_7f_joint4">
      <hardwareInterface>hardware_interface/PositionJointInterface</hardwareInterface>
    </joint>
    <actuator name="sia_7f_joint4_motor">
      <hardwareInterface>hardware_interface/PositionJointInterface</hardwareInterface>
      <mechanicalReduction>1</mechanicalReduction>
    </actuator>
  </transmission>

  <link name="sia_7f_link5">
    <inertial>
      <origin rpy="0 0 0" xyz="-0.000417407802346559 0.141420196765034 0.000500000000005191"/>
      <mass value="14.651521079117"/>
      <inertia ixx="0.0510975342812717" ixy="-0.000597466620243407" ixz="5.20585231291946E-19" iyy="0.0366892670750008" iyz="5.94826194538877E-19" izz="0.0509324272759214"/>
    </inertial>
    <visual>
      <origin rpy="0 0 0" xyz="0 0 0"/>
      <geometry>
        <mesh filename="package://sia_7f_arm_description/meshes/sia_7f_link5.STL"/>
      </geometry>
      <material name="">
        <color rgba="0.752941176470588 0.752941176470588 0.752941176470588 1"/>
      </material>
    </visual>
    <collision>
      <origin rpy="0 0 0" xyz="0 0 0"/>
      <geometry>
        <mesh filename="package://sia_7f_arm_description/meshes/sia_7f_link5_collision.stl"/>
      </geometry>
    </collision>
  </link>

  <joint name="sia_7f_joint5" type="revolute">
    <origin rpy="0 1.5708 0" xyz="-0.0005 0 -0.396"/>
    <parent link="sia_7f_link4"/>
    <child link="sia_7f_link5"/>
    <axis xyz="0 0 1"/>
    <limit effort="1" lower="-1.57" upper="0" velocity="1"/>
  </joint>

  <transmission name="sia_7f_joint5_trans">
    <type>transmission_interface/SimpleTransmission</type>
    <joint name="sia_7f_joint5">
      <hardwareInterface>hardware_interface/PositionJointInterface</hardwareInterface>
    </joint>
    <actuator name="sia_7f_joint5_motor">
      <hardwareInterface>hardware_interface/PositionJointInterface</hardwareInterface>
      <mechanicalReduction>1</mechanicalReduction>
    </actuator>
  </transmission>

  <link name="sia_7f_gripper">
    <inertial>
      <origin rpy="0 0 0" xyz="3.26845956272193E-08 0 -0.0226728796969817"/>
      <mass value="0.217996643227686"/>
      <inertia ixx="0.000209321112569424" ixy="-3.62599757727355E-21" ixz="-9.38585083804093E-11" iyy="0.000281938189060602" iyz="-1.21047816736719E-19" izz="0.000329709951218745"/>
    </inertial>
    <visual>
      <origin rpy="0 0 0" xyz="0 0 0"/>
      <geometry>
        <mesh filename="package://sia_7f_arm_description/meshes/sia_7f_gripper.STL"/>
      </geometry>
      <material name="">
        <color rgba="0.792156862745098 0.819607843137255 0.933333333333333 1"/>
      </material>
    </visual>
    <collision>
      <origin rpy="0 0 0" xyz="0 0 0"/>
      <geometry>
        <mesh filename="package://sia_7f_arm_description/meshes/sia_7f_gripper_collision.stl"/>
      </geometry>
    </collision>
  </link>

  <joint name="sia_7f_gripper" type="revolute">
    <origin rpy="1.5708 -1.5708 0" xyz="0 0.2471 0.0005"/>
    <parent link="sia_7f_link5"/>
    <child link="sia_7f_gripper"/>
    <axis xyz="0 0 -1"/>
    <limit effort="1" lower="-1.57" upper="1.57" velocity="1"/>
  </joint>

  <transmission name="sia_7f_gripper_trans">
    <type>transmission_interface/SimpleTransmission</type>
    <joint name="sia_7f_gripper">
      <hardwareInterface>hardware_interface/PositionJointInterface</hardwareInterface>
    </joint>
    <actuator name="sia_7f_gripper_motor">
      <hardwareInterface>hardware_interface/PositionJointInterface</hardwareInterface>
      <mechanicalReduction>1</mechanicalReduction>
    </actuator>
  </transmission>
 
  <link name="7f_gripper_left_inner_knuckle">
    <inertial>
      <origin rpy="0 0 0" xyz="0.00025000000001961 -0.0449993055501968 0"/>
      <mass value="0.057581795389513"/>
      <inertia ixx="0.000136033138239505" ixy="4.57842646598595E-07" ixz="8.97069281394419E-21" iyy="5.36252772626667E-05" iyz="2.53729353711014E-20" izz="8.47531530961166E-05"/>
    </inertial>
    <visual>
      <origin rpy="0 0 0" xyz="0 0 0"/>
      <geometry>
        <mesh filename="package://sia_7f_arm_description/meshes/7f_gripper_left_inner_knuckle.STL"/>
      </geometry>
      <material name="">
        <color rgba="0.792156862745098 0.819607843137255 0.933333333333333 1"/>
      </material>
    </visual>
    <collision>
      <origin rpy="0 0 0" xyz="0 0 0"/>
      <geometry>
        <mesh filename="package://sia_7f_arm_description/meshes/7f_gripper_left_inner_knuckle_collision.stl"/>
      </geometry>
    </collision>
  </link>
  <joint name="7f_gripper_left_inner_knuckle_joint" type="revolute">
    <origin rpy="1.5708 -4.5705E-17 -1.5929E-16" xyz="0.0115 0 -0.058"/>
    <parent link="sia_7f_gripper"/>
    <child link="7f_gripper_left_inner_knuckle"/>
    <axis xyz="0 0 -1"/>
    <limit effort="1" lower="-1" upper="1" velocity="1"/>
    <mimic joint="sia_7f_finger_joint" multiplier="1" offset="0"/>
  </joint>
  <link name="7f_gripper_left_outer_finger">
    <inertial>
      <origin rpy="0 0 0" xyz="0.000250000000019193 -0.0449993055501973 5.55111512312578E-17"/>
      <mass value="0.100689431754135"/>
      <inertia ixx="0.00017912511445164" ixy="6.74735770950199E-07" ixz="-8.79238926756737E-20" iyy="5.76782985603803E-05" iyz="2.09544631085124E-20" izz="0.000126092678843798"/>
    </inertial>
    <visual>
      <origin rpy="0 0 0" xyz="0 0 0"/>
      <geometry>
        <mesh filename="package://sia_7f_arm_description/meshes/7f_gripper_left_outer_finger.STL"/>
      </geometry>
      <material name="">
        <color rgba="0.792156862745098 0.819607843137255 0.933333333333333 1"/>
      </material>
    </visual>
    <collision>
      <origin rpy="0 0 0" xyz="0 0 0"/>
      <geometry>
        <mesh filename="package://sia_7f_arm_description/meshes/7f_gripper_left_outer_finger_collision.stl"/>
      </geometry>
    </collision>
  </link>

  <joint name="sia_7f_finger_joint" type="revolute">
    <origin rpy="1.5708 -4.5705E-17 -2.7062E-16" xyz="0.0525 0 -0.028"/>
    <parent link="sia_7f_gripper"/>
    <child link="7f_gripper_left_outer_finger"/>
    <axis xyz="0 0 -1"/>
    <limit effort="1" lower="-1" upper="0" velocity="1"/>
  </joint>

  <transmission name="sia_7f_finger_joint_trans">
    <type>transmission_interface/SimpleTransmission</type>
    <joint name="sia_7f_finger_joint">
      <hardwareInterface>hardware_interface/PositionJointInterface</hardwareInterface>
    </joint>
    <actuator name="sia_7f_finger_joint_motor">
      <hardwareInterface>hardware_interface/PositionJointInterface</hardwareInterface>
      <mechanicalReduction>1</mechanicalReduction>
    </actuator>
  </transmission>

  <link name="7f_gripper_left_inner_finger">
    <inertial>
      <origin rpy="0 0 0" xyz="-0.0308057717440851 0.0521402204950119 9.78399816720099E-09"/>
      <mass value="0.124284698819219"/>
      <inertia ixx="0.000170315985615428" ixy="5.06080501976649E-05" ixz="8.12452749909555E-12" iyy="7.73818037393233E-05" iyz="-8.74033706885298E-11" izz="0.000168251176255428"/>
    </inertial>
    <visual>
      <origin rpy="0 0 0" xyz="0 0 0"/>
      <geometry>
        <mesh filename="package://sia_7f_arm_description/meshes/7f_gripper_left_inner_finger.STL"/>
      </geometry>
      <material name="">
        <color rgba="0.792156862745098 0.819607843137255 0.933333333333333 1"/>
      </material>
    </visual>
    <collision>
      <origin rpy="0 0 0" xyz="0 0 0"/>
      <geometry>
        <mesh filename="package://sia_7f_arm_description/meshes/7f_gripper_left_inner_finger_collision.stl"/>
      </geometry>
    </collision>
  </link>
  <joint name="7f_gripper_left_inner_finger_joint" type="revolute">
    <origin rpy="3.1416 2.7062E-16 0" xyz="0.0005 -0.089999 0"/>
    <parent link="7f_gripper_left_outer_finger"/>
    <child link="7f_gripper_left_inner_finger"/>
    <axis xyz="0 0 1"/>
    <limit effort="1" lower="-1" upper="1" velocity="1"/>
    <mimic joint="sia_7f_finger_joint" multiplier="-1.0" offset="0"/>
  </joint>
  <!-- ############# #######################################################-->
  <joint
    name="7f_gripper_left_inner_finger_knuckle_joint"
    type="fixed">
    <parent
      link="7f_gripper_left_inner_finger" />
    <child
      link="7f_gripper_left_outer_finger" />
  </joint>

  <link name="7f_gripper_right_inner_knuckle">
    <inertial>
      <origin rpy="0 0 0" xyz="-0.000249999999980433 -0.0449993055501972 1.11022302462516E-16"/>
      <mass value="0.057581795389513"/>
      <inertia ixx="0.000136033138239506" ixy="-4.57842646526924E-07" ixz="2.1159994208404E-20" iyy="5.36252772626659E-05" iyz="6.96442899953669E-21" izz="8.47531530961168E-05"/>
    </inertial>
    <visual>
      <origin rpy="0 0 0" xyz="0 0 0"/>
      <geometry>
        <mesh filename="package://sia_7f_arm_description/meshes/7f_gripper_right_inner_knuckle.STL"/>
      </geometry>
      <material name="">
        <color rgba="0.792156862745098 0.819607843137255 0.933333333333333 1"/>
      </material>
    </visual>
    <collision>
      <origin rpy="0 0 0" xyz="0 0 0"/>
      <geometry>
        <mesh filename="package://sia_7f_arm_description/meshes/7f_gripper_right_inner_knuckle_collision.stl"/>
      </geometry>
    </collision>
  </link>
  <joint name="7f_gripper_right_inner_knuckle_joint" type="revolute">
    <origin rpy="1.5708 -4.5705E-17 2.464E-16" xyz="-0.0115 0 -0.058"/>
    <parent link="sia_7f_gripper"/>
    <child link="7f_gripper_right_inner_knuckle"/>
    <axis xyz="0 0 -1"/>
    <limit effort="1" lower="-1" upper="1" velocity="1"/>
    <mimic joint="sia_7f_finger_joint" multiplier="-1" offset="0"/>
  </joint>
  <link name="7f_gripper_right_outer_finger">
    <inertial>
      <origin rpy="0 0 0" xyz="-0.000249999999980766 -0.0449993055501982 0"/>
      <mass value="0.100689431754135"/>
      <inertia ixx="0.000179125114451641" ixy="-6.74735770846122E-07" ixz="-5.80811190437573E-20" iyy="5.76782985603793E-05" iyz="-2.1590416438529E-21" izz="0.000126092678843797"/>
    </inertial>
    <visual>
      <origin rpy="0 0 0" xyz="0 0 0"/>
      <geometry>
        <mesh filename="package://sia_7f_arm_description/meshes/7f_gripper_right_outer_finger.STL"/>
      </geometry>
      <material name="">
        <color rgba="0.792156862745098 0.819607843137255 0.933333333333333 1"/>
      </material>
    </visual>
    <collision>
      <origin rpy="0 0 0" xyz="0 0 0"/>
      <geometry>
        <mesh filename="package://sia_7f_arm_description/meshes/7f_gripper_right_outer_finger_collision.stl"/>
      </geometry>
    </collision>
  </link>
  <joint name="7f_gripper_right_outer_finger_joint" type="revolute">
    <origin rpy="1.5708 -4.5705E-17 -2.7062E-16" xyz="-0.0525 0 -0.028"/>
    <parent link="sia_7f_gripper"/>
    <child link="7f_gripper_right_outer_finger"/>
    <axis xyz="0 0 -1"/>
    <limit effort="1" lower="-1" upper="1" velocity="1"/>
    <mimic joint="sia_7f_finger_joint" multiplier="-1" offset="0"/>
  </joint>
  <link name="7f_gripper_right_inner_finger">
    <inertial>
      <origin rpy="0 0 0" xyz="0.0308057717439587 -0.0521402204950057 9.78399650186645E-09"/>
      <mass value="0.12428469881922"/>
      <inertia ixx="0.000170315985615459" ixy="5.06080501976394E-05" ixz="-8.12452750782823E-12" iyy="7.73818037392954E-05" iyz="8.7403370609002E-11" izz="0.00016825117625543"/>
    </inertial>
    <visual>
      <origin rpy="0 0 0" xyz="0 0 0"/>
      <geometry>
        <mesh filename="package://sia_7f_arm_description/meshes/7f_gripper_right_inner_finger.STL"/>
      </geometry>
      <material name="">
        <color rgba="0.792156862745098 0.819607843137255 0.933333333333333 1"/>
      </material>
    </visual>
    <collision>
      <origin rpy="0 0 0" xyz="0 0 0"/>
      <geometry>
        <mesh filename="package://sia_7f_arm_description/meshes/7f_gripper_right_inner_finger_collision.stl"/>
      </geometry>
    </collision>
  </link>
  <joint name="7f_gripper_right_inner_finger_joint" type="revolute">
    <origin rpy="5.7309E-17 4.8572E-16 1.2328E-32" xyz="-0.0005 -0.089999 0"/>
    <parent link="7f_gripper_right_outer_finger"/>
    <child link="7f_gripper_right_inner_finger"/>
    <axis xyz="0 0 -1"/>
    <limit effort="1" lower="-1" upper="1" velocity="1"/>
    <mimic joint="sia_7f_finger_joint" multiplier="1.0" offset="0"/>
  </joint>
</robot>

